2022-05-16 19:41:03,314 ERROR: Exception on /user/test_user [GET] [in /home/max/Python/microblog/venv/lib/python3.10/site-packages/flask/app.py:1455]
Traceback (most recent call last):
  File "/home/max/Python/microblog/venv/lib/python3.10/site-packages/sqlalchemy/engine/base.py", line 1819, in _execute_context
    self.dialect.do_execute(
  File "/home/max/Python/microblog/venv/lib/python3.10/site-packages/sqlalchemy/engine/default.py", line 732, in do_execute
    cursor.execute(statement, parameters)
sqlite3.OperationalError: no such table: Followers

The above exception was the direct cause of the following exception:

Traceback (most recent call last):
  File "/home/max/Python/microblog/venv/lib/python3.10/site-packages/flask/app.py", line 2077, in wsgi_app
    response = self.full_dispatch_request()
  File "/home/max/Python/microblog/venv/lib/python3.10/site-packages/flask/app.py", line 1525, in full_dispatch_request
    rv = self.handle_user_exception(e)
  File "/home/max/Python/microblog/venv/lib/python3.10/site-packages/flask/app.py", line 1523, in full_dispatch_request
    rv = self.dispatch_request()
  File "/home/max/Python/microblog/venv/lib/python3.10/site-packages/flask/app.py", line 1509, in dispatch_request
    return self.ensure_sync(self.view_functions[rule.endpoint])(**req.view_args)
  File "/home/max/Python/microblog/venv/lib/python3.10/site-packages/flask_login/utils.py", line 303, in decorated_view
    return current_app.ensure_sync(func)(*args, **kwargs)
  File "/home/max/Python/microblog/app/routes.py", line 72, in user
    return render_template("user.html", user=user, posts=posts, form=form)
  File "/home/max/Python/microblog/venv/lib/python3.10/site-packages/flask/templating.py", line 148, in render_template
    return _render(
  File "/home/max/Python/microblog/venv/lib/python3.10/site-packages/flask/templating.py", line 128, in _render
    rv = template.render(context)
  File "/home/max/Python/microblog/venv/lib/python3.10/site-packages/jinja2/environment.py", line 1301, in render
    self.environment.handle_exception()
  File "/home/max/Python/microblog/venv/lib/python3.10/site-packages/jinja2/environment.py", line 936, in handle_exception
    raise rewrite_traceback_stack(source=source)
  File "/home/max/Python/microblog/app/templates/user.html", line 1, in top-level template code
    {% block content %}
  File "/home/max/Python/microblog/app/templates/user.html", line 9, in block 'content'
    {% if user.about_me %}
  File "/home/max/Python/microblog/venv/lib/python3.10/site-packages/sqlalchemy/orm/dynamic.py", line 376, in count
    return self._generate(sess).count()
  File "/home/max/Python/microblog/venv/lib/python3.10/site-packages/sqlalchemy/orm/query.py", line 3163, in count
    return self._from_self(col).enable_eagerloads(False).scalar()
  File "/home/max/Python/microblog/venv/lib/python3.10/site-packages/sqlalchemy/orm/query.py", line 2888, in scalar
    ret = self.one()
  File "/home/max/Python/microblog/venv/lib/python3.10/site-packages/sqlalchemy/orm/query.py", line 2865, in one
    return self._iter().one()
  File "/home/max/Python/microblog/venv/lib/python3.10/site-packages/sqlalchemy/orm/query.py", line 2903, in _iter
    result = self.session.execute(
  File "/home/max/Python/microblog/venv/lib/python3.10/site-packages/sqlalchemy/orm/session.py", line 1696, in execute
    result = conn._execute_20(statement, params or {}, execution_options)
  File "/home/max/Python/microblog/venv/lib/python3.10/site-packages/sqlalchemy/engine/base.py", line 1631, in _execute_20
    return meth(self, args_10style, kwargs_10style, execution_options)
  File "/home/max/Python/microblog/venv/lib/python3.10/site-packages/sqlalchemy/sql/elements.py", line 325, in _execute_on_connection
    return connection._execute_clauseelement(
  File "/home/max/Python/microblog/venv/lib/python3.10/site-packages/sqlalchemy/engine/base.py", line 1498, in _execute_clauseelement
    ret = self._execute_context(
  File "/home/max/Python/microblog/venv/lib/python3.10/site-packages/sqlalchemy/engine/base.py", line 1862, in _execute_context
    self._handle_dbapi_exception(
  File "/home/max/Python/microblog/venv/lib/python3.10/site-packages/sqlalchemy/engine/base.py", line 2043, in _handle_dbapi_exception
    util.raise_(
  File "/home/max/Python/microblog/venv/lib/python3.10/site-packages/sqlalchemy/util/compat.py", line 207, in raise_
    raise exception
  File "/home/max/Python/microblog/venv/lib/python3.10/site-packages/sqlalchemy/engine/base.py", line 1819, in _execute_context
    self.dialect.do_execute(
  File "/home/max/Python/microblog/venv/lib/python3.10/site-packages/sqlalchemy/engine/default.py", line 732, in do_execute
    cursor.execute(statement, parameters)
sqlalchemy.exc.OperationalError: (sqlite3.OperationalError) no such table: Followers
[SQL: SELECT count(*) AS count_1 
FROM (SELECT user.id AS user_id, user.username AS user_username, user.email AS user_email, user.password_hash AS user_password_hash, user.about_me AS user_about_me, user.last_seen AS user_last_seen 
FROM user, "Followers" 
WHERE "Followers".followed_id = ? AND "Followers".follower_id = user.id) AS anon_1]
[parameters: (2,)]
(Background on this error at: https://sqlalche.me/e/14/e3q8)
